Workbook
Name _ftn1: '9 - e-RS API Overarching reqs'!#REF!
Name _ftn1: '9.1 - NHS e-RS Session APIs '!#REF!
Name _ftn1: '9.2 - NHS e-RS Ref Data APIs'!#REF!
Name _ftn1: '9.3 - NHS e-RS CRI APIs'!#REF!
Name _ftnref1: '9 - e-RS API Overarching reqs'!$C$7
Name _ftnref1: '9.1 - NHS e-RS Session APIs '!$C$7
Name _ftnref1: '9.2 - NHS e-RS Ref Data APIs'!$C$7
Name _ftnref1: '9.3 - NHS e-RS CRI APIs'!$C$7
Name _Toc456344471: 'Approval Gateways'!#REF!
Name _Toc456344472: 'Approval Gateways'!#REF!
Name _Toc456344473: 'Approval Gateways'!#REF!
Name AccessMethod: [1]Lists!$B$66:$B$73
Name AccessMethod: [2]Lists!$B$66:$B$73
Name AccessMethod: [3]Lists!$B$52:$B$59
Name AccessMethod: [3]Lists!$B$52:$B$59
Name AccessMethod: [3]Lists!$B$52:$B$59
Name AccessMethod: [3]Lists!$B$52:$B$59
Name AccessMethod: [4]Lists!$B$52:$B$59
Name AccessMethod: [4]Lists!$B$52:$B$59
Name AccessMethod: Lists!$B$66:$B$73
Name Approval: [1]Lists!$B$109:$B$110
Name Approval: [2]Lists!$B$109:$B$110
Name Approval: [3]Lists!$B$95:$B$96
Name Approval: [3]Lists!$B$95:$B$96
Name Approval: [3]Lists!$B$95:$B$96
Name Approval: [3]Lists!$B$95:$B$96
Name Approval: Lists!$B$109:$B$110
Name Assessment: #REF!
Name Assessment: #REF!
Name Assessment: [5]Lists!$B$82:$B$85
Name Assessment: [5]Lists!$B$82:$B$85
Name Assessment: [5]Lists!$B$82:$B$85
Name Assessment: [5]Lists!$B$82:$B$85
Name Assessment: [4]Lists!$B$82:$B$85
Name Bundles: [6]Lists!$E$2:$E$27
Name Bundles: [7]Lists!$E$2:$E$27
Name Bundles: [8]Lists!$E$2:$E$27
Name Change: [6]Lists!$G$2:$G$5
Name Change: [7]Lists!$G$2:$G$5
Name Change: [8]Lists!$G$2:$G$5
Name Compliance_Level: #REF!
Name Compliance_Level: #REF!
Name Compliance_Level: #REF!
Name Compliance_Level: #REF!
Name Compliance_Level: #REF!
Name Compliance_Level: #REF!
Name ComplianceLevel: [9]Data!$A$3:$A$6
Name CompliantStatus: [10]Data!$A$3:$A$6
Name DMS: [6]Lists!$K$2:$K$9
Name DMS: [7]Lists!$K$2:$K$9
Name DMS: [8]Lists!$K$2:$K$9
Name EndUserOrgType: Lists!$B$41:$B$50
Name IGSoCResult: [1]Lists!$B$83:$B$86
Name IGSoCResult: [3]Lists!$B$69:$B$72
Name IGSoCResult: [3]Lists!$B$69:$B$72
Name IGSoCResult: [3]Lists!$B$69:$B$72
Name IGSoCResult: [3]Lists!$B$69:$B$72
Name IGSoCResult: [4]Lists!$B$69:$B$72
Name IGSoCResult: [4]Lists!$B$69:$B$72
Name IGSoCResult: Lists!$B$83:$B$86

Sheet Cover
B2: Title | C2: NHS e-Referral Service APIs - Target Operating Model (TOM) Self-Evaluation Checklist
B3: Description | C3: Record of self-certified statements and evidence mapped against each requirement.
B4: Document Reference | C4: Target Operating Model - e-RS APIs - Self-Evaluation Checklist v 1.2
B5: NHS Digital Contact Centre (NIC) Reference - please quote on all correspondence to NHS Digital.
B6: Date | C6: 43175
B7: Version | C7: 1.2
B8: Status | C8: Approved
B9: Author(s) | C9: Sami Mohammed, Paul Denton, Zubeir Tai, Alastair Jepps
B11: Document History
B12: The version history of this document:
B14: Version | C14: Version Description | D14: Date of Production | E14: Author
B15: 1.0 | C15: New - Initial Pilot Release for Review | D15: 43153 | E15: S. Mohammed
B16: 1.1 | C16: Review Comments from External Teams | D16: 43171 | E16: S. Mohammed
B17: 1.2 | C17: Final approval | D17: 43175 | E17: S. Mohammed
B24: Supporting References
B25: This TOM references the following documents:
B27: Document | C27: Title | D27: Reference
B28: Base 1 | C28: ATOS Compliance Manual | D28: Atos_Origin_Supplier_Master_Guide.pdf
B29: Base 2 | C29: API Ecosystem on Developer Library | D29: https://developer.nhs.uk/library/systems/e-rs/
B30: Base 3 | C30: Information Governance Toolkit | D30: https://www.igt.hscic.gov.uk/Home.aspx?tk=427985175981346&cb=e0bf992f-dba9-4ad8-80b9-bf548428cf57&lnv=7&clnav=YES
B31: Base 4 | C31: NHS Business Partners mini-guide | D31: https://digital.nhs.uk/article/296/NHS-Business-Partners
B32: Base 5 | C32: Process for Connecting to Core National NHS Systems | D32: https://digital.nhs.uk/article/296/NHS-Business-Partners
B33: Base 6 | C33: GPSoC IG Requirements V4 | D33: HSCIC-FNT-TO-TAR-0223.01 IG Requirements V4 - 0.9.docx
B35: Reviewers
B36: This document must be reviewed by the following people:
B38: Reviewer name | C38: Title / Responsibility | D38: Version | E38: Date
B39: Paul Denton | C39: NHS e-RS Programme Manager | D39: V1.1 | E39: 11/03/2018
B40: Siouxsie Trenaman | C40: NHS e-RS Compliance Manager
B41: Tony Marsh | C41: NHS e-RS Project Manager
B42: Nicholas Apperley | C42: Demographics Technical Architect | D42: V1.0 | E42: 02/03/2018
B43: Andy Dickinson | C43: Information Governance Subject Matter Expert
B44: Matt Wyatt | C44: Security Subject Matter Expert
B45: Phil Morton | C45: Head of Solution Assurance
B46: David Pool | C46: Test & Assurance Manager
B47: Zahid Hayat | C47: Test & Assurance Manager
B48: Vicki Depledge | C48: Head of Technical Support Services
B49: Richard Dobson | C49: Senior Test and Assurance Manager
B50: Nicola Young | C50: Senior Test and Assurance Manager
B51: Nigel Saville | C51: Senior Test and Assurance Analyst | D51: V1.0 | E51: 28/02/2018
B52: Mike Anderson | C52: Professional Services - Safety Engineer
...

Sheet Introduction
B1: NHS e-Referral Service APIs - Target Operating Model (TOM) Self-Evaluation Checklist
B25: *Please note the following colour coding conventions: Green = End User Organisation; Red = Solution Supplier; and, Blue = NHS Digital.
B27: Checklist Section
D29: This section captures contact details for all involved organisations. Required for Phase 1A | J29: KEY FOR COMPLETION
J30: The colour key used throughout this document is:
J31: NHS Digital to complete
J32: Supplier to complete
D33: Captures Solution Supplier information. Required for Phase 1A and 1B | J33: End User organisation to complete
J34: Supplier/End User collaborate to complete
D37: Captures Organisation information, data usage, and the associated legal agreements. Required for Phase 1A
D41: Shows the NHS Digital recognised topologies. One must be selected as part of the evaluation process. Required for Phase 1A
D46: This section assesses the technical and integration architecture, and highlights any risks or issues. Required for Phase 2
D50: This section considers the IG implications of the new interface - assessing the Controls in place against the Business Scenario. Required for Phase 2
D54: This section assesses whether there may be clinical safety implications of the new interface. Required for Phase 2
D58: This section ensures the correct Service Management processes are in place to assist the deployment and maintenance once the application is deployed in to the live environment. Required for Phase 2
D62: This section is the assessment of e-RS API consumer applications against the e-RS API requirements. Required for Phase 1B

Sheet User Guide
B2: Roles and Responsibilities
B3: The table below outlines the roles and responsibilities for those who will either complete, review or approve the Target Operating Model (TOM):
B5: Role | E5: Responsibility within the TOM Completion, Review and Approval Process
B6: End User Organisation | E6: Organisation responsible for the deployment Responsible for completing the relevant sections of the TOM, demonstrating compliance against the requirement set Responsible for providing acceptance of the End Product (Phase 2) Accountable for reviewing the content of the completed TOM and accepting any key risks, exclusions or mitigations (Phase 2) May also be the Solution Supplier, if a client end product is being developed in-house Organisation which will be the end user of the Solution Supplier's Consuming Product
B7: Solution Supplier | E7: Organisation responsible for developing the product which will be used by the end user Responsible for completing the relevant sections of the TOM, demonstrating the e-RS API Client compliance against the requirement set
B8: NHS Digital | E8: Responsible for reviewing the relevant section of the TOM have been completed Accountable for ensuring any key risks which stem from non-compliance against the Target Operating Model are highlighted to the End User Organisation Responsible for ensuring guidance is provided to the End User Organisation and Solution Supplier for Target Operating Model completion Provides approval for the Client to be deployed Provides statement if technical conformance has been achieved
B11: TOM Completion Guidance
B12: The notes below provide guidance to those who will be completing the TOM:

Sheet Approval Gateways
A1: Phase 1A - Usage and Settings - Approved by NHS Digital
B2: This section details the individual who will assess the Usage and Settings information provided within the End User Organisation tab of this Target Operating Model. This assessment will provide basis for granting access to e-RS APIs.
B3: The assessement may require further action - please see the Section 'Outcome of Usage and Settings Statement'.
B5: Category | C5: Role | D5: Guidance | E5: Organisation | F5: Name | G5: Job Title | H5: Approval Date
B6: NHS Digital Approver
C7: NHS e-RS Programme Head & Information Asset Owner | D7: The NHS e-RS Programme Head & Information Asset Owner with overall accountability for the data. The assessment is for the usage and setting only and not for any other aspect of the TOM. | E7: NHS Digital
B9: Category | C9: Area | D9: Approved/Rejected | E9: Reason | H9: Date
B10: Approval/Rejection
C11: System Usage | D11: Select
C12: System Setting | D12: Select
C13: Actual Data User Organisation | D13: Select
B15: Category | D15: Detail | H15: Date
B16: Outcome of Usage and Settings Statement
C17: Action
A19: Phase 1B - Technical Conformance - Approved by NHS Digital
B20: This section details the individual who will assess the technical conformance of the developed Client based on the outcome of testing and the completion of sections 5 to 9.x.
B21: Technical conformance will provide basis for issuing the e-RS API Conformance Certificate to the Supplier and commencing e-RS API development.
B23: Category | C23: Role | D23: Guidance | E23: Organisation | F23: Name | G23: Job Title | H23: Approval Date
B24: NHS Digital Approver
C25: Solution Assurance Team | D25: The Solution Assurance Test & Assurance Team (e-RS Integration) is responsible for assuring the supplier e-RS API development. | E25: NHS Digital
C26: e-RS API Certificate Number | D26: This is the e-RS API Technical conformance certificate number, for the version of the Client (End Product) indicated on the certificate. | E26: IAC-nnnn-nnnnnnnn
A28: Phase 2 - Target Operating Model Assessment - Approved by the End User Organisation
B29: This section details the individual who will assess the information provided in the entire Target Operating Model. Any risks highlighted during the completion of the TOM are accepted by and will be managed by the Approver of the End User Organisation.
B30: Once the TOM is approved by this approval panel it should be sent to the Solution Supplier to forward to NHS Digital for audit purposes. This approval will be used as basis to proceed with the deployment of the Service.
B32: Category | C32: Role | D32: Guidance | E32: Organisation | F32: Name | G32: Job Title | H32: Approval Date
B33: End User Organisation Approver
C34: End User Organisation Owner | D34: I am authorised to accept my organisation’s responsibilities as set out in the TOM and End User Agreement Policy, having entered into contract with the Solution Supplier, approve use of the Service. I understand the TOM has been provided to assist my organisation in assuring the Service and there may be additional implications and risks to consider prior to acceptance. I confirm my organisation has assured itself and accepts its obligations and responsibilities (and any risks highlighted) as set out in the TOM and End User Policy.
C35: Other individuals as required

Sheet 1 - Contact Log
A1: Step 1 - Contacts Log | D1: Back to Introduction
B3: This section provides a reference list of stakeholders who MAY need to be contacted, as an aid to building a virtual project team.
B4: It allows specific contact details to be recorded for those roles which are relevant - both for day-to-day practical purposes, and as an audit trail of those involved.
B5: (Note that there may be multiple individuals for some stakeholder roles, and extra lines should be inserted as necessary).
B7: Category | C7: Item | D7: Guidance | E7: Name | F7: Job Title | G7: Email | H7: Telno | I7: Type
B8: End User Organisation's Stakeholders
C9: End User Organisation Owner | D9: The End User Organisations Executive with overall accountability for the project, this assessment, and any associated risks. | I9: Info
C10: Project Board Executive | D10: The End User Organisations Executive directly leading the project. | I10: Info
C11: Project Manager | D11: The End User Organisations project manager. | I11: Info
C12: Other Project Team Members | D12: Other project team members (Add lines and details as required). | I12: Info
C13: ICT Manager(s) | D13: ICT Manager for the End User Organisation(s) involved in the project. | I13: Info
C14: Other key ICT contacts | D14: Other key End User Organisation ICT contacts - e.g. for architecture / design, operations etc. | I14: Info
C15: User representative(s) | D15: User representatives - e.g. for requirements and testing activities. | I15: Info
C16: SIRO(s) | D16: The Senior Information Risk Owner responsible for signoff of IG related risks (Note: May be multiple individuals if several organisations are involved). | I16: Info
C17: Clinical Safety Officer(s) | D17: The Clinical Safety Officer responsible for signoff of Clinical Safety related risks as defined by SCCI0160 Standard, mandated by NHS England (Note: May be multiple individuals if several organisations are involved). | I17: Info
C18: End User Policy Signatory | D18: The individual that will be the recipient of the End User Policy for a signature. | I18: Info
B19: Solution Supplier Stakeholders
C20: Supplier | D20: Supplier Name. | I20: Info
C21: Project Manager | D21: The Supplier project manager. | I21: Info
C22: Technical Contact | D22: The technical contact / architect. | I22: Info
C23: Executive Sponsor | D23: The Executive sponsor / escalation point. | I23: Info
C24: Clinical Safety Officer(s) | D24: The Clinical Safety Officer responsible for signoff of Clinical Safety related risks as defined by SCCI0129 Standard, mandated by NHS England (Note: May be multiple individuals if several organisations are involved). | I24: Info
C25: Connection Agreement Signatory | D25: The individual that will be the recipient of the End User Policy for a signature. | I25: Info
B26: Other Supplier's Stakeholders | D26: Repeat and add other suppliers as required
C27: Other Supplier 1 | D27: Supplier Name. | I27: Info
C28: Supplier Project Manager | D28: The Supplier project manager. | I28: Info
C29: Supplier Technical | D29: The technical contact / architect. | I29: Info
C30: Supplier Executive Sponsor | D30: The Executive sponsor / escalation point. | I30: Info
C31: Clinical Safety Officer(s) | D31: The Clinical Safety Officer responsible for signoff of Clinical Safety related risks as defined by SCCI0129 Standard, mandated by NHS England (Note: May be multiple individuals if several organisations are involved). | I31: Info
B32: NHS Digital Stakeholders
C33: NHS Digital Clinical Safety Group contact | D33: Depending on the assessment of clinical safety implications, may need to be used as an advice / escalation point for any Clinical Safety risks. (May be n/a if not involved). | I33: Info
C34: NHS Digital Release Manager | D34: Will be used as an advice / escalation point for general impacts. | I34: Info
C35: NHS Digital Assurance contact | D35: Will advise on conformance in general. | I35: Info
C36: Service Contact | D36: Will advise on programme specific details (e.g. training, support). | I36: Info
B37: Other Stakeholders
C38: Other contact details | D38: Any other contacts relevant to the specific project - to be added as necessary. | I38: Info

Sheet 2 - Supplier Information 
A1: Step 2 - Solution Supplier Information | D1: Back to Introduction
B3: This section captures basic information about the Solution Supplier and the system consuming the data from the NHS e-Referral Service.
B5: Category | C5: Item | D5: Guidance | E5: Response | F5: Type
B6: Client System Details | D6: This details the consuming e-RS API product.
C7: Product | D7: The product requesting and receiving data from the NHS e-RS API solution. | F7: Info
C8: Solution Supplier | D8: The supplier of the product. | F8: Info
C9: Organisation Data Service (ODS) Code | D9: A single ODS code of the Solution Supplier or End User - see https://odsportal.hscic.gov.uk/. | F9: Action
C10: Is This Product Being Assessed | D10: If the product is already deployed further assessment of this product is not required. | F10: Info
C11: First of Type | D11: Yes or No. If the system has previously implemented this interface (e.g. at another End User Organisation) it would not be a first of type.If No, indicate organisation name. | F11: Info
C12: Version and Configuration Details | D12: Where known and relevant, provide any further details about the product configuration (e.g. licensed APIs workflow suites, relevant parameter settings etc.). | F12: Info
B13: Client IG Toolkit Compliance | D13: Details of the IG Toolkit compliance status (information can be found on the IG toolkit - https://www.igt.hscic.gov.uk/ )
C14: Current IG Toolkit (IGT) Version | D14: The score quoted below should be using the latest IGT version - an IGT assessment must be completed and published annually. | F14: Action
C15: Organisation Type | D15: Select best match from list. | F15: Action
C16: Date Started | D16: Date started IG Toolkit. | F16: Action
C17: Date Published | D17: Date IG Toolkit was published. | F17: Action
C18: Self-assessed Grade | D18: IG Toolkit compliance grade; if relevant, provide details in "Response text". | F18: Action
B19: Client IGSoC Compliance | D19: Details of the IGSoC compliance status (for information see - https://digital.nhs.uk/health-social-care-network/new-to-hscn/connecting-to-HSCN#The HSCN Connection Agreement/ )
C20: Organisation Type (if different from IGT Organisation Type) | D20: Select best match from list. | F20: Action
C21: Start date | D21: Date received IGSoC. | F21: Action
B22: Client Interface Overview | D22: This details the actual use and physical storage of the data
C23: Overview Description | D23: Provide a brief introductory overview describing at a high level what the interface does and why it is being introduced e.g. screenshots, screencam of the application. | F23: Action
C24: Data Usage | D24: Provide a description of how the data retrieved from Spine will be used e.g. displayed on a screen with the subject of the data in attendance, a batch job with no user interface. | F24: Action
C25: Data Storage | D25: Describe by who and where the data will be held/stored e.g. on End User Organisation servers, on servers .belonging to third party suppliers commissioned by an End User Organisation to do work on behalf of the End User Organisation | F25: Action
C26: User Base | D26: Explain in broad terms who will be using the system (e.g. number of users, typical job roles e.g. social worker, doctor, pharmacist, administrator). | F26: Action
C27: Key Dates | D27: Outline any key dates relevant to the self-assessment process (e.g. target Go-Live dates. | F27: Info

Sheet 3 - End User Organisation 
A1: Step 3 - End User Organisation | C1: Back to Introduction
A3: This section captures basic information about the e-RS API access request. Used to determine the application type and approval route.
A4: Where Column A is marked 'PDS' the item is only mandatory if this TOM includes a PDS deployment
A5: Further guidance on this Section can be obtained from the Ecosystem on Developer Library
A7: Cat. | B7: Item | C7: Guidance | D7: Date / List / Code | E7: Response text - or code or list and explanatory text | F7: Assess
A8: Health or Social Care Organisation Details (End User Organisation)
B9: NHS Digital Contact Centre Reference | C9: NIC reference. Please quote on all correspondence to NHS Digital. | F9: NYA
B10: Organisation Name | C10: Full name required. | F10: NYA
B11: Contact Name | F11: NYA
B12: Contact Postal Address | F12: NYA
B13: Contact Postcode | F13: NYA
B14: Contact Email Address | F14: NYA
B15: Contact Telephone | C15: Direct dial number please. | F15: NYA
B16: ODS Code | C16: A single ODS code of the organisation with responsibility for the demographics query event. See https://odsportal.hscic.gov.uk/ - insert code in yellow box. | F16: NYA
B17: Organisation Type | C17: Select from list. | F17: NYA
B18: NHS or not | C18: Select from list. For Mixed and Non-NHS staff explain in "Response" box. | D18: NYK | F18: NYA
B19: Data Controller(s) | C19: Provide role (not name), organisation and address. Definition of a Data Controller can be found https://ico.org.uk/for-organisations/guide-to-data-protection/key-definitions/. | F19: NYA
B20: Data Processor(s) | C20: Provide role (not name), organisation and address. Definition of a Data Processor can be found https://ico.org.uk/for-organisations/guide-to-data-protection/key-definitions/. | F20: NYA
B21: Date this form first Submitted | C21: Subsequent dates can be in the "Response" column. | F21: NYA
A22: Data Protection Act Information
A23: PDS | B23: Data Protection Act Registration details | C23: Provide a web link. | F23: NYA
A24: PDS | B24: Fair Processing Notice (FPN) details | C24: Also known as a Privacy Notice. Provide a web link to your organisation's notice Must be fully compliant with the guidance of https://ico.org.uk/for-organisations/guide-to-data-protection/privacy-notices-transparency-and-control/ and Independent Group Advising on the Release of Data (IGARD). Further information about the IGARD guidance will be provided. | F24: NYA
A25: Existing Data Sharing Framework Contract | C25: Must be in place in some instances before the request is approved | E25: If none existing, one will need to be raised
A26: PDS | B26: Reference | C26: This may reference the former HSCIC. | F26: NYA
A27: PDS | B27: Date of Signature by NHS Digital | C27: The effective start date. | F27: NYA
A28: PDS | B28: Expiry Date | F28: NYA
A29: Existing Data Sharing Agreement (DSA) | C29: If more than one - additional information in "Response".
A30: PDS | B30: Reference | C30: Summary of purpose in "Response" box with DSA reference. NB Each purpose will have a separate DSA. | F30: NYA
A31: PDS | B31: Date of Signature by NHS Digital | C31: The effective start date. | F31: NYA
A32: PDS | B32: Expiry Date | F32: NYA
A33: Local Data Sharing Agreements
A34: PDS | B34: For multiple local organisations | C34: Provide an overview of the local Data Sharing Agreements and embed documents. | F34: NYA
A35: PDS Data and Access Method
A36: PDS | B36: PDS data already held | C36: If appropriate. List data items. | F36: NYA
A37: PDS | B37: Current PDS access method | C37: If appropriate. Select from list. | D37: NYK | F37: NYA
A38: PDS | B38: PDS data requested | C38: List data items. | F38: NYA
A39: PDS | B39: Requested PDS access method | C39: Select from list. | D39: NYK | F39: NYA
A40: PDS | B40: Application provider name | C40: For Spine Integrated systems and Spine Mini Service Provider (SMSP) only. | F40: NYA
A41: PDS | B41: Registration Authority (RA) and ODS code | C41: For Spine Integrated systems and Summary Care Record Application (SCRa) only. Insert RA ODS Code in yellow box. | F41: NYA
A42: Request Details | C42: Embed documents as appropriate.
...

Sheet 4 - Topology
B1: Step 4 - Please Select the Topology which matches the Deployment | I1: Back to Introduction
C3: This section is for the Solution Suppliers and Deploying Care Organisation to articulate their implementation topology.
C4: Topology A represents a single implementation where by the solution supplier and care organisation are focused on a single product.
C5: Topology B represents the use care where a solution supplier product is deployed across multiple care organisations.
B8: Deployment Topology A | N8: Deployment Topology B
H10: Select | I10: N | S10: Select | W10: N
C28: Category | E28: Item | H28: Guidance | N28: Response | Y28: Type
C29: Supporting Topology Information | H29: This details key information about the Solution Supplier Topology
E30: Topology Justification | H30: Provide an outline for how the application meets the selected system topology. | Y30: Action
E31: No. of End Points | H31: Outline how many End Points are going to be used for the deployment (i.e. single end point or multiple end points per deployment). | Y31: Action
E32: End Point Registration | H32: Is the intention to use existing live end points or use new end points. If existing End Points are to be used confirm the relevant details here (inc ASID). | N32: . | Y32: Action
E33: Data Storage | H33: Is the data persistent in the Supplier's system and can be accessed by the Solution Supplier as well as the End User Organisation? | Y33: Action

Sheet 5 - Architecture
A1: Step 5 - Architecture | D1: Back to Introduction
B3: This section examines the system architecture to ensure that it is fit for purpose.
B4: It provides best-practice guidance which End User Organisations must consider when assuring their own architectures.
B5: The intention is for this spreadsheet to act as a checklist and cross-reference to ensure that all necessary points are covered in more detailed technical documentation.
B6: For Deployment topology B (Aggregators) - the Deploying Organisation is expected to provide details of level and coverage of the Ready for Operations (applicable to new implementations) and Volume and Performance assessment (testing) they will look to implement to support IO-01 and IO-04 requirments
B8: Category | C8: Item | D8: Guidance | E8: Action By | F8: Compliance Level | G8: Additional Notes / References | H8: Type
B9: IT Operations Planning
B10: IO-01 | C10: Data Centre Resilience and Manageability | D10: Ensuring that consideration is given to hosting the solution with an appropriate level of resilience and reliability. Topics to cover include: - Resilience / Failover - Identification of any single points of failure - Load balancing design and failure scenarios - Backup and Recovery - Disaster Recovery - Alerting and Monitoring | E10: To be completed by the Supplier to provide best-practice guidance to the End User Organisation | F10: Please select … | H10: Action
B11: IO-02 | C11: Go Live Planning | D11: Ensuring that the Go Live process is adequately planned, including contingency planning. Topics to cover include: - Cutover and Fallback - Installation and Configuration - Network worthiness - Data Migration | E11: To be completed by the Supplier to provide best-practice guidance to the End User Organisation | F11: Please select … | H11: Action
B12: IO-03 | C12: Operational Checks | D12: Planning for checks that the system is operating correctly. Topics to cover include: - Audit - Journaling - Usability | E12: To be completed by the Supplier to provide best-practice guidance to the End User Organisation | F12: Please select … | H12: Action
B13: IO-04 | C13: End-to-End Performance Design Review | D13: Ensuring that the solution is performant under the anticipated usage load. Topics to cover include: - Estimated usage volumetrics - Service Levels required - End-to-end performance implications of transactions via the new interface. - Volume and Performance (V&P) testing and / or performance design review | E13: To be completed by the Supplier to provide best-practice guidance to the End User Organisation | F13: Please select … | H13: Action
B14: IO-05 | C14: Deployment topology B (Aggregators) - Confirmation of Ready For Operations and Volume and Performance Assessment | D14: Assessment activity coverage provision Topics to cover include: - Define the level of RFO assessment to be undertaken (applicable only to new infrastructure deployments) - Confirm the coverage of Volume and Performance assessment to be implemented. | E14: To be completed by the Supplier to provide best-practice guidance to the End User Organisation | F14: Please select … | H14: Action
B15: IO-06 | C15: Throttling | D15: The Client supplier must demonstrate ability to throttle their (batch) solution per [api endpoint] to limit X connections (X to be agreed with Programme) | E15: To be completed by the Supplier to provide best-practice guidance to the End User Organisation | F15: Please select … | H15: Action
B16: Integration Architecture
B17: IA-01 | C17: Integration Architecture | D17: Ensuring that an appropriate integration architecture is in place. Topics to cover include: - Use of integration middleware (e.g. Trust Integration Engine, Toolkit Middleware) - Interface usage (Can existing interfaces be used and/or are any new interfaces or messages needed?) - Adapters (Consideration of any new adapters that may be needed to convert between data formats) - End-to-End Reliability (e.g. acknowledgements, retries, transactionality) - Sequencing (Mechanisms used to manage business and technical level sequencing and orchestration of messages) - Backwards and Forwards compatibility (The technical approach to message versioning, and the approach to handling potential changes in the message definitions) | E17: To be completed by the Supplier to provide best-practice guidance to the End User Organisation | F17: Please select … | H17: Action
B18: IA-02 | C18: Interface Change Planning | D18: Ensuring that the processes and procedures in place to make sure that the interface can be maintained and kept up-to-date. For example, what would be the impact of a change to an upstream system, and how would this be notified and managed? This is likely to include regression testing | E18: To be completed by the Supplier to provide best-practice guidance to the End User Organisation | F18: Please select … | H18: Action
B19: Information Architecture
B20: IN-01 | C20: Data Quality Review | D20: Ensuring that the solution supports data quality - and in particular that the new interface does not propagate low quality or misleading data between systems. Topics to cover include: - Message validation (The approach to technical message validation - specifically how sending systems ensure that generated messages are valid) - Data content quality (The mechanisms in place to ensure that data passing via the new interface is complete, consistent, timely and accurate) - Data Concurrency (Ensuring that data made available via the new interface is kept up-to-date, and that updates of "stale" data are not able to corrupt upstream system) | E20: To be completed by the Supplier to provide best-practice guidance to the End User Organisation | F20: Please select … | H20: Action
B21: IN-02 | C21: Use of Data Standards | D21: Ensuring that the solution makes appropriate use of all relevant data standards. Topics to cover include: - Use of NHS Digital Data Standards including: • SNOMED – for reference terminology • NHS Data Dictionary – for administrative codes • ICD-10 and OPCS – for reporting - Reasons for any differences from the above. - Does the project represent an opportunity to migrate towards these NHS Digital data standards? - Data Mappings (Are any mappings between different data standards required? If yes, indicate what these mappings are - and confirm that it is both possible and clinically safe to perform the translation) | E21: To be completed by the Supplier to provide best-practice guidance to the End User Organisation | F21: Please select … | H21: Action
B22: Clinical Safety
B23: CL-01 | C23: Technical Clinical Safety Review | D23: Ensuring that the technical aspects of the solution provide adequate support for clinical safety Topics to cover include: - What is the impact on care or provision of clinical of any integration layer becoming unavailable? - What is the impact of a transactional failure, or a failure of a single request in a sequence of interactions ? - Are there any implications for “chains of systems” – such that changes to one system have clinical safety implications for other systems with which it is integrated? - How are users informed of a failure so that they can react accordingly ? - How are applications informed of a failure to that they can support their users, and leave their systems in a safe, stable state ? - How are failures logged so that operations staff can understand what went wrong, and react accordingly ? | E23: To be completed by the Supplier to provide best-practice guidance to the End User Organisation | F23: Please select … | H23: Action
B24: Architecture Collateral
B25: AC-01 | C25: Infrastructure View (Optional) | D25: Infrastructure architecture connotes the architecture of the low level hardware, networks, and system software (sometimes called "middleware") that supports the applications software and business systems of an enterprise. | E25: To be completed by the Supplier to provide best-practice guidance to the End User Organisation | F25: Please select … | H25: Action
B26: AC-02 | C26: Security Architecture | D26: Security Architecture is the design artifacts that describe how the security controls (= security countermeasures) are positioned and how they relate to the overall systems architecture. These controls serve the purpose to maintain the system's quality attributes such as confidentiality, integrity and availability. | E26: To be completed by the Supplier to provide best-practice guidance to the End User Organisation | F26: Please select … | H26: Action
B27: AC-03 | C27: Operations Architecture (Optional) | D27: Diagram indicating service delivery, service support, Risk management, Security, & Operations Whichever elements are pertinent to the supplier solution. See here for example: https://www.linkedin.com/pulse/why-operations-architecture-sarthak-banerjee/ | E27: To be completed by the Supplier to provide best-practice guidance to the End User Organisation | F27: Please select … | H27: Action
B28: AC-04 | C28: Data Architecture | D28: The Data architecture view deals with the architecture of the storage, retrieval, processing, archiving, and security of data. It looks at the flow of data as it is stored and processed, and at what components will be required to support and manage both storage and processing. | E28: To be completed by the Supplier to provide best-practice guidance to the End User Organisation | F28: Please select … | H28: Action
B29: AC-05 | C29: Network Architecture (Optional) | D29: Network Architecture diagrams visualize the computer networks topology and equipment connections and arrangement. Used to visually document the architecture of computer and telecommunication networks | E29: To be completed by the Supplier to provide best-practice guidance to the End User Organisation | F29: Please select … | H29: Action
B30: AC-06 | C30: Solution Architecture | D30: Overall diagram to depict the top level design of the supplier solution. | E30: To be completed by the Supplier to provide best-practice guidance to the End User Organisation | F30: Please select … | H30: Action
B31: AC-07 | C31: Sequence / Activity Diagrams | D31: These should be included for all business flows, including exception handling. Activity diagram depict the control flow from one activity to another, conditional structures, loops, concurrency, and exceptions. Sequence diagram depict the sequence of messages flow from one object to another, how their messages/events are exchanged in what time-order. | E31: To be completed by the Supplier to provide best-practice guidance to the End User Organisation | F31: Please select … | H31: Action

Sheet 6 - IG and Security
A1: Step 6 - Information Governance and Security | D1: Back to Introduction
B3: This section confirms the Information Governance (IG) controls required, and the mechanisms for implementation of each.
B4: The emphasis is on highlighting the business requirement for a particular control, rather than mandating that a particular technical mechanism be used.
B5: For each IG control a number of recognised technical implementation mechanisms are listed, and use of these pre-established mechanisms can accelerate implementation.
B6: Where a non-standard technical implementation mechanism is proposed then the checklist will highlight the need for further review and risk assessment by the End User Organisation's Senior Information Risk Owner (SIRO).
B8: This IG checklist applies to all e-RS API client systems. It should be noted there exists additional client specific requirements detailed in the '9.X - e-RS API Reqs' worksheet.
B10: Category | C10: Control | D10: Guidance | E10: Actioned By | F10: Compliance | G10: Additional Notes / References | H10: Type
B11: Business Scenario(s) | D11: This section relates to identifying the type of business scenario which the interface will support. This is because different business scenarios will require different levels of IG controls. Answer "Yes" or "No" to indicate whether each of the business scenarios in the list below apply to the interface | E11: Actioned by | F11: Compliance | G11: Additional Notes/References
C12: Demographic Query | D12: Demographic data is queried under the control of the receiving system. | E12: …...on behalf of the Client Supplier | H12: Action
C13: Demographic Update | D13: Demographic data is updated via the interface. | E13: …...on behalf of the Client Supplier | H13: Action
C14: Clinical Query | D14: Clinical data is queried under the control of the receiving system | E14: …...on behalf of the Client Supplier | H14: Action
C15: Clinical Update | D15: Clinical data is updated via the interface. | E15: …...on behalf of the Client Supplier | H15: Action
C16: CP-IS Query | D16: CP-IS data is queried under the control of the receiving system. | E16: …...on behalf of the Client Supplier | H16: Action
C17: CP-IS Update | D17: CP-IS data is updated via the interface. | E17: …...on behalf of the Client Supplier | H17: Action
C18: V&M Query | D18: V&M data is queried under the control of the receiving system. | E18: …...on behalf of the Client Supplier | H18: Action
C19: V&M Update | D19: V&M data is updated via the interface | E19: …...on behalf of the Client Supplier | H19: Action
C20: FGM RIS Query | D20: FGM RIS data is queried under the control of the receiving system. | E20: …...on behalf of the Client Supplier | H20: Action
C21: FGM RIS Update | D21: FGM RIS data is updated via the interface. | E21: …...on behalf of the Client Supplier | H21: Action
B22: Process Controls | D22: These Process Controls are always relevant | F22: =IF(F23="No", "FAIL", "PASS") -> PASS | H22: =IF(F$11="DEMO_READ_ONLY", "SHOULD", "MUST") -> MUST
C23: Information Security Management System (ISMS) | D23: Is a formal Information Security Management System in place? An Information Security Management System (ISMS) is defined as that part of the overall management system, based on a business risk approach, to establish, implement, operate, monitor, review, maintain and improve information security. BS EN ISO/IEC 27001:2017 is the relevant standard | E23: …...on behalf of the End User Organisation | H23: Action
B24: Technical Controls | D24: These Technical Controls are always relevant | F24: =IF(OR(F25="No",F26="No",F27="No",F28="No",F29= "No",F30="No",F31= "No",F32= "No",F33= "No",F34= "No",F35= "No"), "FAIL", IF(OR(F25="Other",F27="Other",F28="Other", F29="Other", F30="Other", F31="Other", F33="Other"), "CHECK","PASS")) -> PASS | H24: =IF(F$11="DEMO_READ_ONLY", "SHOULD", "MUST") -> MUST
C25: Secure Communications | D25: Are the requirements for secure communications met? For example, encrypting data in transit All data in transit must be encrypted using an approved cipher suite, in this instance TLS1.2. See approved Cryptographic Algorithms Document http://webarchive.nationalarchives.gov.uk/20161101131024/http://systems.digital.nhs.uk/infogov/security/infrasec/gpg | E25: …...on behalf of the Client Supplier | H25: Action
C27: Storage | D27: Are there adequate controls of data in storage? For example are storage devices (e.g. File system, Database) encrypted at rest and / or located in a secure area? See approved Cryptographic Algorithms Document http://webarchive.nationalarchives.gov.uk/20161101131024/ http://systems.digital.nhs.uk/infogov/security/infrasec/gpg Guidance provided by NCSC here https://www.ncsc.gov.uk/guidance/b3-data-security | E27: …...on behalf of the Client Supplier | H27: Action
C28: Time Stamping | D28: Is an accurate time source in place? Servers must be time synchronised to an agreed NHS N3 NTP synchronized time server and use this time in messages and logs. Date and time between systems (e.g. for use in audit logs) should be synchronised within 250 milliseconds of the NASP-provided or National Network Time Servers. These are sources of UTC time (known locally as GMT) which is the time that all message interactions MUST be time stamped with (i.e. message or API interaction creation time). | E28: …...on behalf of the Client Supplier | H28: Action
C29: Network Access | D29: Are the guidelines for network access controls met? See https://nww.carecertisp.digital.nhs.uk/display/CC/NHS+Digital+Good+Practice+Guides 'Access Control Lists'/'Firewall Technologies'/'LAN Security' | E29: …...on behalf of the Client Supplier | H29: Action
C30: Workstation Access | D30: Are workstations and servers adequately secured? See referenced guidance from the National Institutes of Standards Technology (NIST) for more details | E30: …...on behalf of the Client Supplier | H30: Action
C31: Content Commitment | D31: Are Digital Signatures used where necessary to sign content and / or authenticate the identity of a sender? This may be not applicable, in which case leave blank and note as "Not applicable" in the Additional Notes column | E31: …...on behalf of the Client Supplier | H31: Action
C33: Security Testing | D33: Has a penetration test been completed and an action plan been developed to mitigate any vulnerabilities identified? | E33: …...on behalf of the Client Supplier and End User Organisation | H33: Action
H34: Action
B36: IG Controls (Baseline) | D36: These Baseline IG controls are always relevant | F36: =IF(OR(F37="None",F38="None",F39="None",F40= "None",F41= "None",F42= "None"), "FAIL", IF(OR(F37="Other",F38="Other", F39="Other", F40="Other", F41="Other", F42="Other"), "CHECK","PASS")) -> PASS | H36: =IF(F$11="DEMO_READ_ONLY", "SHOULD", "MUST") -> MUST
C37: Authentication | D37: What mechanism is provided for secure authentication of users? Recognised authentication (log-on) mechanisms include: - Spine smartcard - Other strong authentication e.g. two-factor token logon Other mechanisms (e.g. username and password )should be noted as "Other" and described further in Additional Notes. | E37: …...on behalf of the Client Supplier | H37: Action
C38: Role Based Access Control (RBAC) | D38: What access control approach is implemented? Role Based Access Control should limit users so that they can only access system functionality relevant to their job role Recognised mechanisms include both National and Local RBAC If Local RBAC is selected, please provide further details (this may be in the form of a reference to additional documentation) Other mechanisms (e.g. limiting physical access to the system )should be noted as "Other" and described further in Additional Notes. | E38: …...on behalf of the Client Supplier | H38: Action
C39: Audit | D39: Is a full audit trail provided? See “Audit Requirements - v3.0” (within downloadable 'Requirements Pack') for details which MUST be complied with: https://developer.nhs.uk/library/systems/e-rs/. | E39: …...on behalf of the Client Supplier | H39: Action
C41: Data Retention | D41: Is data retention provided, in line with NHS retention standards? See https://digital.nhs.uk/codes-of-practice-handling-information for more details of minimum retention periods for different data types. | E41: …...on behalf of the Client Supplier | H41: Action
B43: IG Controls (Clinical) | D43: These IG controls are only applicable for systems handling patient identifiable clinical data (Answer n/a if not applicable) | F43: =IF(OR(F44="None"), "FAIL", IF(OR(F44="Other"), "CHECK","PASS")) -> PASS | H43: =IF(F47="DEMO_READ_ONLY", "SHOULD", "MUST") -> MUST
C44: Legitimate Relationships (LR) | D44: What mechanism is used to ensure that only clinicians with a legitimate relationship with a patient are able to access their clinical records? Recognised mechanisms include - National LR checking - Locally Inferred LR (e.g. based on the clinician being a member of a relevant workgroup in the local system) Please use "Additional Notes" to provide further details of the approach used. | E44: …...on behalf of the End User Organisation | H44: Action
B45: IG Controls (Clinical Cross Organisation) | D45: These IG Controls are only applicable for systems passing patient identifiable clinical data across organisational boundaries (Answer n/a if not applicable) | F45: =IF(OR(F46="None"), "FAIL", IF(OR(F46="Other"), "CHECK","PASS")) -> PASS | H45: =IF(F49="DEMO_READ_ONLY", "SHOULD", "MUST") -> MUST
C46: DCR Consent to Share | D46: How is it ensured that patient consent is checked for any sharing of the Detailed Care Record (DCR) across organisational boundaries? Recognised mechanisms include: - National DCR Consent Check - checking against the DCR Consent Flag on Spine (PDS) before allowing sharing of clinical data across boundaries - Block sending externally - ensuring that clinical data is only shared within the same Trust - Referral Based Sharing - ensuring that clinical data is only shared in relation to directly supporting a referral Please use "Additional Notes" to provide further details of the approach used. | E46: …...on behalf of the End User Organisation | H46: Action
B47: End-to-End Information Flows | D47: This section looks at the overall end-to-end information flows and examines the potential for data leakage or data integrity issues as a result of implementing the new interface | F47: =IF(OR(F49="Yes",F50="Yes"), "FAIL", "PASS") -> PASS | H47: =IF(F51="DEMO_READ_ONLY", "SHOULD", "MUST") -> MUST
C48: End-to-End Information Flows | D48: Provide reference to documentation (e.g. diagram) showing the information flows to / from the system being assessed and other systems in the estate. Specifically, the purpose is to highlight: i) The potential ultimate destinations of any patient identifiable Spine-originated data passing through this system. ii) The potential original sources of any data updates made to Spine via this system. | E48: …...on behalf of the End User Organisation | H48: Action
...

Sheet 7 - Clinical Safety
A1: Step 7 - Clinical Safety | D1: Back to Introduction
B3: This section confirms actions required to mitigate Clinical Safety risks.
B4: Dependant on the clinical setting of your Health IT system, this section must be completed or have input from either; - a Clinical Safety Officer or suitably trained and experienced clinicians - a Social Care Professional, registered by the General Social Care Council and MUST be signed off as indicated in the Additional Stakeholder Involvement section below.
B5: Clinical safety signoff requirements are determined below on completing questions 1 to 5, there are five possible outcomes; 1. None Required 2. Local Only (Non Clinical) 3. Local Only (Clinical Safety Related) SCCI0129 / SCCI0160 needs to be applied 4. NHS Digital Clinical Safety Group Assistance Required 5. The System falls under the category of a Medical Device and guidance should be sought from the MHRA If further guidance is needed then the NHS Digital Clinical Safety Group may be contacted on clinical.safety@nhs.net
B7: Category | C7: Item | D7: Guidance | E7: Actioned By | F7: Compliance | G7: Additional Notes / References | H7: Type
B8: Clinical Safety
B9: CS-01 | C9: Medical Device? | D9: Q1 Is your system a Medical Device or eligible to be a Medical Device? Output: If the answer is ‘No’ further safety assurance work may be required. Continue to Q2 If the answer is ‘Yes’ the system falls under the category of a medical device and guidance should be sought from the MHRA. | E9: …...on behalf of the End User Organisation | H9: Action
B10: CS-02 | C10: Updating Spine? | D10: Q2 Is the System updating data held on the Spine? Output: If the answer is ‘Yes’, further safety assurance may be required in accordance with SCCI0129 / 0160. | E10: …...on behalf of the End User Organisation | H10: Action
B11: CS-031 | C11: System Function? Is there a requirement on Clinical Safety? | D11: Q3.1: Is the System integrating with other systems (e.g. a parent System, examples may include a patient administration system or prescribing system)? Output: If the answer is ‘Yes’, further safety assurance may be required in accordance with SCCI0129 / SCCI0160. | E11: …...on behalf of the End User Organisation | H11: Action
B12: CS-032 | D12: Q3.2 Is the system used solely to automate general office functions to assist in payments and billing etc.? | E12: …...on behalf of the End User Organisation | H12: Action
B13: CS-033 | D13: Q3.3 Is the System a transactional one (e.g. Used to book, amend and cancel appointments or to issue a prescription or repeat medication)? Output: If the answer is ‘Yes’, further safety assurance may be required. | E13: …...on behalf of the End User Organisation | H13: Action
B14: CS-034 | D14: Q3.4 Is this a calculation and / or monitoring System (e.g. recording patient Clinical Information), which is used to record, track and/or maintain health for ongoing Clinical support? Output: If the answer is ‘Yes’, further safety assurance may be required in accordance. | E14: …...on behalf of the End User Organisation | H14: Action
B15: CS-04 | C15: Safety Issues? | D15: Q4 Were any clinical safety issues identified by the technical clinical safety review performed in the "Architecture CL-01" section of this checklist? | E15: …...on behalf of the End User Organisation | H15: Action
B16: CS-051 | C16: Safety Compliance | D16: Q5.1 As the client and where a Hazard log is provided by NHS Digital have you: a) reviewed the Hazard log? b) implemented appropriate local mitigations? c) transferred the Hazards/Mitigations into the local business processes and accepted ownership of residual risk(s)? | E16: …...on behalf of the End User Organisation | H16: Action
B17: CS-052 | D17: Q5.2 In applying the questions set out in Q2 through Q3, does the output recommend further safety assurance as required under SCCI0129 or 0160? | E17: …...on behalf of the End User Organisation
B18: CS-053 | D18: Q5.3 As the client, have you conducted a formal Risk Assessment and identified Clinical Safety Hazards in accordance with SCCI0129 / 0160? | E18: …...on behalf of the End User Organisation | H18: Action
B19: CS-054 | D19: Q5.4 As the client, is there a formal Safety Case and incorporating Hazard log? | E19: …...on behalf of the End User Organisation | H19: Action
B20: CS-055 | D20: Q5.5 As the client, is there: a) a Clinical Safety Officer or suitably trained and experienced clinicians or b) a Social Care Professional, registered by the General Social Care Council. who has signed off the system and interface? | E20: …...on behalf of the End User Organisation | H20: Action
B22: Clinical Safety Signoff Level | C22: =IF(OR(F9="Yes"), HYPERLINK("https://www.gov.uk/government/organisations/medicines-and-healthcare-products-regulatory-agency", "5 - The System falls under the category of a Medical Device and guidance should be sought from the MHRA"), IF(F10="Yes", HYPERLINK("http://systems.digital.nhs.uk/clinsafety", "4- NHS Digital Clinical Safety Group Assistance Required"), IF(OR(F11="Yes",F13="Yes",F14="Yes"),"3 - Local Only (Clinical Safety Related) SCCI0129 /SCCI0160 needs to be applied", IF(F12="Yes","2 - Local Only (Non Clinical)","1 - None Required")))) -> 1 - None Required | D22: See Clinical Risk Management standards and implementation guidance documents for details http://systems.digital.nhs.uk/clinsafety
B24: Additional Information Required
B26: =IF(MID(C$22,1,1)>"2", "RISK ASSESSMENT - have you conducted a formal Risk Assessment and identified Clinical Safety Hazards in accordance withSCCI0129 / 0160 (See Clinical Safety Framework, Chapter 4 for more details)", "")
B27: =IF(MID(C$22,1,1)>"2", "DOCUMENTARY EVIDENCE - is there a formal Safety Case and incorporating Hazard log. (See Clinical Safety Framework, Chapter 4 for more details)", "")
B28: =IF(F$15="Yes", "SAFETY ISSUES - Provide documentation on any clinical safety implications of any issues identified in the Architecture section of this checklist: (See Clinical Safety Guidance, Chapter 4 for more details)", "")
B31: Additional Stakeholder Involvement
B34: =IF(MID(C$22,1,1)>"4", HYPERLINK("https://www.gov.uk/government/organisations/medicines-and-healthcare-products-regulatory-agency", "MHRA - For more information on Medical Device regulation follow this link"), "")
B35: =IF(MID(C$22,1,1)>"1", "CSO - the local Clinical Safety Officer or Social Care Professional must sign off the interface", "")
B36: =IF(MID(C$22,1,1)>"2", "CSG - Assistance from the NHS Digital Clinical Safety group is available. Contact clinical.safety@NHS Digital.gov.uk", "")
B37: =IF(MID(C$22,1,1)>"3", "CSG - Signoff from the NHS Digital Clinical Safety group is required. Contact clinical.safety@NHS Digital.gov.uk", "")

Sheet 8 - Service 
A1: Step 8 - Service Readiness | D1: Back to Introduction
B3: This section ensures the correct operational processes are in place.
B4: The information is to be submitted by the Supplier however it is anticipated input will be required from the End User Organisation to answer SR-1.
B5: Submitted information will be recorded by the NHS Digital Service Management team.
B6: It is the responsibility of the End User Organisation to agree the specific deployment approach with the Supplier
B8: Category | C8: Activity | D8: Activity Description / Help Text | E8: Compliance Level | F8: Evidence | G8: Comments | H8: Type
B9: Client Supplier
B10: SR-01 | C10: Client Supplier Service Desk contact number | D10: Telephone number for operational contact regarding the service. | E10: Please select … | H10: Action
B11: SR-02 | C11: Client Supplier Service desk email address | D11: Primary email address. | E11: Please select … | H11: Action
B12: SR-03 | C12: Support Hours | D12: State the hours of support provided by the Client Supplier Service Desk. | E12: Please select … | H12: Action
B13: SR-04 | C13: NHS Digital National Service Desk | D13: Confirm that the Supplier has registered with the National Service Desk. | E13: Please select … | H13: Action
B14: SR-05 | C14: Out of hours contact number (state if same as above) | D14: If there is an on-call rota, please advise how this will be provided to the NHS Digital Bridge. | E14: Please select … | H14: Action
B15: SR-06 | C15: Operational contact numbers | D15: Please provide local organisation chart where possible, with the roles pertaining to this service explained. | E15: Please select … | H15: Action
B16: SR-07 | C16: Incident Management | D16: Confirm that the Supplier has an incident management process in place that it will use with Commissioning Organisations and that is consistent with the NHS Digital Incident Management process. Attach evidence of any service and incident management processes to be used. | E16: Please select … | H16: Action
B17: SR-08 | C17: Incident Severity Levels | D17: Please provide the incident severity levels that you will apply for this service with associated guidance on usage. Please indicate SLA response times for all incident severity types. E.g. Severity Level 1 (Critical): HSSI Severity Level 2 (High): HSSI Severity Level 3 (Medium) Severity Level 4 (Low) Severity Level 5 (Very Low) | E17: Please select … | H17: Action
B18: SR-09 | C18: High Severity Service Incident Manager | D18: Please provide either a name or the rota for performing this function. If the named contact/s will change regularly, please advise how the updated details will be provided to the NHS Digital Service Bridge. | E18: Please select … | H18: Action
B19: SR-10 | C19: Escalation and Complaints Process | D19: Please provide the escalation process for this service. Further guidance is included below*. | E19: Please select … | H19: Action
B20: SR-11 | C20: Escalation Contacts (all relevant levels) | D20: Name, email and phone numbers of all escalation contacts with the escalation level associated with each contact. | E20: Please select … | H20: Action
B21: SR-12 | C21: Anticipated Go Live date for the service with Commissioning Organisation users | D21: If the Go-Live will be phased then anticipated dates and timeframes for the service to be introduced with end users. | E21: Please select … | H21: Action
B22: End User Organisation
B23: SR-13 | C23: Operational contacts and contact details (phone, email) | D23: Please provide local organisation chart where possible, with the roles pertaining to this service explained. | E23: Please select … | H23: Action
B24: SR-14 | C24: Escalation and Complaints Process | D24: Please provide the escalation process for this service. Further guidance is included below*. | E24: Please select … | H24: Action
B25: SR-15 | C25: Escalation Contacts (all relevant levels) | D25: Name, email and phone numbers of all escalation contacts with the escalation level associated with each contact. | E25: Please select … | H25: Action
B26: SR-16 | C26: Anticipated Go Live date for the service with Commissioning Organisation users | D26: If the Go-Live will be phased then anticipated dates and timeframes for the service to be introduced with end users. | E26: Please select … | H26: Action
B29: * GUIDANCE The escalation and complaints process shall comply with the following principles: - The party raising the Escalation or Complaint shall be kept informed of progress at an appropriate interval as agreed with the party raising the Escalation - All Escalations and Complaints shall be managed to an appropriate conclusion with agreed remedial actions to prevent re-occurrence - Escalations and Complaints shall not be closed without the agreement of the party that raised them - Details of all Escalations and Complaints shall be retained on the audit trail for a period of two years - Activity should be undertaken by the party against whom the Complaint was made in order to minimise the re-occurrence of the issues underlying reported Escalations and Complaints.

Sheet 9 - e-RS API Overarching reqs
B1: Step 9 - NHS e-RS API Overarching Requirements | D1: Back to Introduction
B3: This section assesses the application against the published set of Target Operating Model NHS e-RS API pre-requisites
B4: The requirements may be satisfied by a combination of Solution Supplier and End User Organisations design and implementation activity.
B5: Any Semi-compliant or Non-compliance MUST be detailed.
B7: Category / Requirement | C7: Requirement | D7: Requirement Description / Help Text | E7: Guidance | F7: Compliance Level | G7: Supplier Implementation Reference | H7: Additional Notes / References | I7: Test Reference - Matrix | J7: Type
B8: 1. General Requirements
B9: GR-001 | C9: Submission of Signed Connection Agreement and End User Organisation Policyn, inclusive of Ecoystsem-based Special Terms acknowledgement | D9: Documents signed and submitted to NHS Digital | E9: Documents available from https://developer.nhs.uk/library/systems/e-rs/ | F9: Please select … | J9: Action
